2024-03-24 19:30:16,001  ERROR  Internal Server Error: /news/  /mnt/c/Users/User/Desktop/Python/Programms/SkillFactory_projects/News_site/linux_venv/lib/python3.10/site-packages/django/utils/log.py  (<class 'django.template.exceptions.TemplateSyntaxError'>, TemplateSyntaxError("Invalid block tag on line 12: 'trans', expected 'endblock'. Did you forget to register or load this tag?"), <traceback object at 0x7fb1e02c3a40>)
Traceback (most recent call last):
  File "/mnt/c/Users/User/Desktop/Python/Programms/SkillFactory_projects/News_site/linux_venv/lib/python3.10/site-packages/django/template/base.py", line 502, in parse
    compile_func = self.tags[command]
KeyError: 'trans'

During handling of the above exception, another exception occurred:

Traceback (most recent call last):
  File "/mnt/c/Users/User/Desktop/Python/Programms/SkillFactory_projects/News_site/linux_venv/lib/python3.10/site-packages/django/core/handlers/exception.py", line 55, in inner
    response = get_response(request)
  File "/mnt/c/Users/User/Desktop/Python/Programms/SkillFactory_projects/News_site/linux_venv/lib/python3.10/site-packages/django/core/handlers/base.py", line 220, in _get_response
    response = response.render()
  File "/mnt/c/Users/User/Desktop/Python/Programms/SkillFactory_projects/News_site/linux_venv/lib/python3.10/site-packages/django/template/response.py", line 114, in render
    self.content = self.rendered_content
  File "/mnt/c/Users/User/Desktop/Python/Programms/SkillFactory_projects/News_site/linux_venv/lib/python3.10/site-packages/django/template/response.py", line 90, in rendered_content
    template = self.resolve_template(self.template_name)
  File "/mnt/c/Users/User/Desktop/Python/Programms/SkillFactory_projects/News_site/linux_venv/lib/python3.10/site-packages/django/template/response.py", line 72, in resolve_template
    return select_template(template, using=self.using)
  File "/mnt/c/Users/User/Desktop/Python/Programms/SkillFactory_projects/News_site/linux_venv/lib/python3.10/site-packages/django/template/loader.py", line 42, in select_template
    return engine.get_template(template_name)
  File "/mnt/c/Users/User/Desktop/Python/Programms/SkillFactory_projects/News_site/linux_venv/lib/python3.10/site-packages/django/template/backends/django.py", line 33, in get_template
    return Template(self.engine.get_template(template_name), self)
  File "/mnt/c/Users/User/Desktop/Python/Programms/SkillFactory_projects/News_site/linux_venv/lib/python3.10/site-packages/django/template/engine.py", line 175, in get_template
    template, origin = self.find_template(template_name)
  File "/mnt/c/Users/User/Desktop/Python/Programms/SkillFactory_projects/News_site/linux_venv/lib/python3.10/site-packages/django/template/engine.py", line 157, in find_template
    template = loader.get_template(name, skip=skip)
  File "/mnt/c/Users/User/Desktop/Python/Programms/SkillFactory_projects/News_site/linux_venv/lib/python3.10/site-packages/django/template/loaders/cached.py", line 57, in get_template
    template = super().get_template(template_name, skip)
  File "/mnt/c/Users/User/Desktop/Python/Programms/SkillFactory_projects/News_site/linux_venv/lib/python3.10/site-packages/django/template/loaders/base.py", line 28, in get_template
    return Template(
  File "/mnt/c/Users/User/Desktop/Python/Programms/SkillFactory_projects/News_site/linux_venv/lib/python3.10/site-packages/django/template/base.py", line 154, in __init__
    self.nodelist = self.compile_nodelist()
  File "/mnt/c/Users/User/Desktop/Python/Programms/SkillFactory_projects/News_site/linux_venv/lib/python3.10/site-packages/django/template/base.py", line 196, in compile_nodelist
    return parser.parse()
  File "/mnt/c/Users/User/Desktop/Python/Programms/SkillFactory_projects/News_site/linux_venv/lib/python3.10/site-packages/django/template/base.py", line 510, in parse
    raise self.error(token, e)
  File "/mnt/c/Users/User/Desktop/Python/Programms/SkillFactory_projects/News_site/linux_venv/lib/python3.10/site-packages/django/template/base.py", line 508, in parse
    compiled_result = compile_func(self, token)
  File "/mnt/c/Users/User/Desktop/Python/Programms/SkillFactory_projects/News_site/linux_venv/lib/python3.10/site-packages/django/template/loader_tags.py", line 295, in do_extends
    nodelist = parser.parse()
  File "/mnt/c/Users/User/Desktop/Python/Programms/SkillFactory_projects/News_site/linux_venv/lib/python3.10/site-packages/django/template/base.py", line 510, in parse
    raise self.error(token, e)
  File "/mnt/c/Users/User/Desktop/Python/Programms/SkillFactory_projects/News_site/linux_venv/lib/python3.10/site-packages/django/template/base.py", line 508, in parse
    compiled_result = compile_func(self, token)
  File "/mnt/c/Users/User/Desktop/Python/Programms/SkillFactory_projects/News_site/linux_venv/lib/python3.10/site-packages/django/template/loader_tags.py", line 234, in do_block
    nodelist = parser.parse(("endblock",))
  File "/mnt/c/Users/User/Desktop/Python/Programms/SkillFactory_projects/News_site/linux_venv/lib/python3.10/site-packages/django/template/base.py", line 504, in parse
    self.invalid_block_tag(token, command, parse_until)
  File "/mnt/c/Users/User/Desktop/Python/Programms/SkillFactory_projects/News_site/linux_venv/lib/python3.10/site-packages/django/template/base.py", line 555, in invalid_block_tag
    raise self.error(
django.template.exceptions.TemplateSyntaxError: Invalid block tag on line 12: 'trans', expected 'endblock'. Did you forget to register or load this tag?
2024-03-24 19:30:16,309  ERROR  "GET /news/ HTTP/1.1" 500 206916  /mnt/c/Users/User/Desktop/Python/Programms/SkillFactory_projects/News_site/linux_venv/lib/python3.10/site-packages/django/core/servers/basehttp.py  None
2024-03-26 20:04:31,043  ERROR  Internal Server Error: /api-news/  C:\Users\User\Desktop\Python\Programms\SkillFactory_projects\News_site\venv\Lib\site-packages\django\utils\log.py  (<class 'django.core.exceptions.ImproperlyConfigured'>, ImproperlyConfigured('Could not resolve URL for hyperlinked relationship using view name "category-detail". You may have failed to include the related model in your API, or incorrectly configured the `lookup_field` attribute on this field.'), <traceback object at 0x0000029472371D40>)
Traceback (most recent call last):
  File "C:\Users\User\Desktop\Python\Programms\SkillFactory_projects\News_site\venv\Lib\site-packages\rest_framework\relations.py", line 396, in to_representation
    url = self.get_url(value, self.view_name, request, format)
          ^^^^^^^^^^^^^^^^^^^^^^^^^^^^^^^^^^^^^^^^^^^^^^^^^^^^
  File "C:\Users\User\Desktop\Python\Programms\SkillFactory_projects\News_site\venv\Lib\site-packages\rest_framework\relations.py", line 334, in get_url
    return self.reverse(view_name, kwargs=kwargs, request=request, format=format)
           ^^^^^^^^^^^^^^^^^^^^^^^^^^^^^^^^^^^^^^^^^^^^^^^^^^^^^^^^^^^^^^^^^^^^^^
  File "C:\Users\User\Desktop\Python\Programms\SkillFactory_projects\News_site\venv\Lib\site-packages\rest_framework\reverse.py", line 47, in reverse
    url = _reverse(viewname, args, kwargs, request, format, **extra)
          ^^^^^^^^^^^^^^^^^^^^^^^^^^^^^^^^^^^^^^^^^^^^^^^^^^^^^^^^^^
  File "C:\Users\User\Desktop\Python\Programms\SkillFactory_projects\News_site\venv\Lib\site-packages\rest_framework\reverse.py", line 60, in _reverse
    url = django_reverse(viewname, args=args, kwargs=kwargs, **extra)
          ^^^^^^^^^^^^^^^^^^^^^^^^^^^^^^^^^^^^^^^^^^^^^^^^^^^^^^^^^^^
  File "C:\Users\User\Desktop\Python\Programms\SkillFactory_projects\News_site\venv\Lib\site-packages\django\urls\base.py", line 88, in reverse
    return resolver._reverse_with_prefix(view, prefix, *args, **kwargs)
           ^^^^^^^^^^^^^^^^^^^^^^^^^^^^^^^^^^^^^^^^^^^^^^^^^^^^^^^^^^^^
  File "C:\Users\User\Desktop\Python\Programms\SkillFactory_projects\News_site\venv\Lib\site-packages\django\urls\resolvers.py", line 848, in _reverse_with_prefix
    raise NoReverseMatch(msg)
django.urls.exceptions.NoReverseMatch: Reverse for 'category-detail' not found. 'category-detail' is not a valid view function or pattern name.

During handling of the above exception, another exception occurred:

Traceback (most recent call last):
  File "C:\Users\User\Desktop\Python\Programms\SkillFactory_projects\News_site\venv\Lib\site-packages\django\core\handlers\exception.py", line 55, in inner
    response = get_response(request)
               ^^^^^^^^^^^^^^^^^^^^^
  File "C:\Users\User\Desktop\Python\Programms\SkillFactory_projects\News_site\venv\Lib\site-packages\django\core\handlers\base.py", line 197, in _get_response
    response = wrapped_callback(request, *callback_args, **callback_kwargs)
               ^^^^^^^^^^^^^^^^^^^^^^^^^^^^^^^^^^^^^^^^^^^^^^^^^^^^^^^^^^^^
  File "C:\Users\User\Desktop\Python\Programms\SkillFactory_projects\News_site\venv\Lib\site-packages\django\views\decorators\csrf.py", line 65, in _view_wrapper
    return view_func(request, *args, **kwargs)
           ^^^^^^^^^^^^^^^^^^^^^^^^^^^^^^^^^^^
  File "C:\Users\User\Desktop\Python\Programms\SkillFactory_projects\News_site\venv\Lib\site-packages\rest_framework\viewsets.py", line 124, in view
    return self.dispatch(request, *args, **kwargs)
           ^^^^^^^^^^^^^^^^^^^^^^^^^^^^^^^^^^^^^^^
  File "C:\Users\User\Desktop\Python\Programms\SkillFactory_projects\News_site\venv\Lib\site-packages\rest_framework\views.py", line 509, in dispatch
    response = self.handle_exception(exc)
               ^^^^^^^^^^^^^^^^^^^^^^^^^^
  File "C:\Users\User\Desktop\Python\Programms\SkillFactory_projects\News_site\venv\Lib\site-packages\rest_framework\views.py", line 469, in handle_exception
    self.raise_uncaught_exception(exc)
  File "C:\Users\User\Desktop\Python\Programms\SkillFactory_projects\News_site\venv\Lib\site-packages\rest_framework\views.py", line 480, in raise_uncaught_exception
    raise exc
  File "C:\Users\User\Desktop\Python\Programms\SkillFactory_projects\News_site\venv\Lib\site-packages\rest_framework\views.py", line 506, in dispatch
    response = handler(request, *args, **kwargs)
               ^^^^^^^^^^^^^^^^^^^^^^^^^^^^^^^^^
  File "C:\Users\User\Desktop\Python\Programms\SkillFactory_projects\News_site\venv\Lib\site-packages\rest_framework\mixins.py", line 46, in list
    return Response(serializer.data)
                    ^^^^^^^^^^^^^^^
  File "C:\Users\User\Desktop\Python\Programms\SkillFactory_projects\News_site\venv\Lib\site-packages\rest_framework\serializers.py", line 795, in data
    ret = super().data
          ^^^^^^^^^^^^
  File "C:\Users\User\Desktop\Python\Programms\SkillFactory_projects\News_site\venv\Lib\site-packages\rest_framework\serializers.py", line 249, in data
    self._data = self.to_representation(self.instance)
                 ^^^^^^^^^^^^^^^^^^^^^^^^^^^^^^^^^^^^^
  File "C:\Users\User\Desktop\Python\Programms\SkillFactory_projects\News_site\venv\Lib\site-packages\rest_framework\serializers.py", line 713, in to_representation
    return [
           ^
  File "C:\Users\User\Desktop\Python\Programms\SkillFactory_projects\News_site\venv\Lib\site-packages\rest_framework\serializers.py", line 714, in <listcomp>
    self.child.to_representation(item) for item in iterable
    ^^^^^^^^^^^^^^^^^^^^^^^^^^^^^^^^^^
  File "C:\Users\User\Desktop\Python\Programms\SkillFactory_projects\News_site\venv\Lib\site-packages\rest_framework\serializers.py", line 538, in to_representation
    ret[field.field_name] = field.to_representation(attribute)
                            ^^^^^^^^^^^^^^^^^^^^^^^^^^^^^^^^^^
  File "C:\Users\User\Desktop\Python\Programms\SkillFactory_projects\News_site\venv\Lib\site-packages\rest_framework\relations.py", line 564, in to_representation
    return [
           ^
  File "C:\Users\User\Desktop\Python\Programms\SkillFactory_projects\News_site\venv\Lib\site-packages\rest_framework\relations.py", line 565, in <listcomp>
    self.child_relation.to_representation(value)
  File "C:\Users\User\Desktop\Python\Programms\SkillFactory_projects\News_site\venv\Lib\site-packages\rest_framework\relations.py", line 411, in to_representation
    raise ImproperlyConfigured(msg % self.view_name)
django.core.exceptions.ImproperlyConfigured: Could not resolve URL for hyperlinked relationship using view name "category-detail". You may have failed to include the related model in your API, or incorrectly configured the `lookup_field` attribute on this field.
2024-03-26 20:04:31,082  ERROR  "GET /api-news/ HTTP/1.1" 500 203669  C:\Users\User\Desktop\Python\Programms\SkillFactory_projects\News_site\venv\Lib\site-packages\django\core\servers\basehttp.py  None
